Workbook
Name NativeTimeline_Date: #N/A
Name Slicer_Project: #N/A

Sheet Marketing Data
L1: Handwritten | M1: Handwritten | N1: =IF(Table1[[#This Row],[Project]]="ყველა პროექტი",SUMIFS($D:$D,$F:$F,"lead",$A:$A,Table1[[#This Row],[Date]],$G:$G,"YES",$E:$E,"FB"),SUMIFS($D:$D,$F:$F,"lead",$C:$C,Table1[[#This Row],[Project]],$A:$A,Table1[[#This Row],[Date]],$G:$G,"YES",$E:$E,"FB")) -> #VALUE! | O1: =IF(Table1[[#This Row],[Project]]="ყველა პროექტი",SUMIFS($D:$D,$F:$F,Table1[[#Headers],[Lead]],$A:$A,Table1[[#This Row],[Date]],$G:$G,"YES"),SUMIFS($D:$D,$F:$F,Table1[[#Headers],[Lead]],$C:$C,$M1,$A:$A,Table1[[#This Row],[Date]],$G:$G,"YES")) -> #VALUE! | P1: =IF(Table1[[#This Row],[Project]]="ყველა პროექტი",SUMIFS($D:$D,$F:$F,Table1[[#Headers],[Impressions]],$A:$A,Table1[[#This Row],[Date]],$G:$G,"YES"),SUMIFS($D:$D,$F:$F,Table1[[#Headers],[Impressions]],$C:$C,Table1[[#This Row],[Project]],$A:$A,Table1[[#This Row],[Date]],$G:$G,"YES")) -> #VALUE! | Q1: =IF(Table1[[#This Row],[Project]]="ყველა პროექტი",SUMIFS($D:$D,$F:$F,Table1[[#Headers],[Reach]],$A:$A,Table1[[#This Row],[Date]],$G:$G,"YES"),SUMIFS($D:$D,$F:$F,Table1[[#Headers],[Reach]],$C:$C,Table1[[#This Row],[Project]],$A:$A,Table1[[#This Row],[Date]],$G:$G,"YES")) -> #VALUE! | R1: =IF(Table1[[#This Row],[Project]]="ყველა პროექტი",SUMIFS($D:$D,$H:$H,Table1[[#Headers],[Messages Reach]],$A:$A,Table1[[#This Row],[Date]],$G:$G,"YES"),SUMIFS($D:$D,$H:$H,Table1[[#Headers],[Messages Reach]],$C:$C,Table1[[#This Row],[Project]],$A:$A,Table1[[#This Row],[Date]],$G:$G,"YES")) -> #VALUE! | S1: =IF(Table1[[#This Row],[Project]]="ყველა პროექტი",SUMIFS($D:$D,$H:$H,Table1[[#Headers],[Messaging Costs]],$A:$A,Table1[[#This Row],[Date]],$G:$G,"YES"),SUMIFS($D:$D,$H:$H,Table1[[#Headers],[Messaging Costs]],$C:$C,Table1[[#This Row],[Project]],$A:$A,Table1[[#This Row],[Date]],$G:$G,"YES")) -> #VALUE! | T1: =IF(Table1[[#This Row],[Project]]="ყველა პროექტი",SUMIFS($D:$D,$F:$F,Table1[[#Headers],[Facebook Costs]],$A:$A,Table1[[#This Row],[Date]],$G:$G,"YES"),SUMIFS($D:$D,$F:$F,Table1[[#Headers],[Facebook Costs]],$C:$C,Table1[[#This Row],[Project]],$A:$A,Table1[[#This Row],[Date]],$G:$G,"YES")) -> #VALUE! | U1: =Table1[[#This Row],[Facebook Costs]]+Table1[[#This Row],[Web Marketing]] -> #VALUE! | V1: =IF(Table1[[#This Row],[Project]]="ყველა პროექტი",SUMIFS($D:$D,$F:$F,Table1[[#Headers],[Web Marketing]],$A:$A,Table1[[#This Row],[Date]],$G:$G,"YES"),SUMIFS($D:$D,$F:$F,Table1[[#Headers],[Web Marketing]],$C:$C,Table1[[#This Row],[Project]],$A:$A,Table1[[#This Row],[Date]],$G:$G,"YES")) -> #VALUE! | W1: =IF(Table1[[#This Row],[Project]]="ყველა პროექტი",SUMIFS($D:$D,$F:$F,Table1[[#Headers],[Results]],$A:$A,Table1[[#This Row],[Date]],$G:$G,"YES"),SUMIFS($D:$D,$F:$F,Table1[[#Headers],[Results]],$C:$C,Table1[[#This Row],[Project]],$A:$A,Table1[[#This Row],[Date]],$G:$G,"YES")) -> #VALUE! | X1: =IF(Table1[[#This Row],[Project]]="სამგორი",SUMIFS(REPORT!$165:$165,REPORT!$1:$1,'Marketing Data'!L1),IF(Table1[[#This Row],[Project]]="ლისი",SUMIFS(REPORT!$171:$171,REPORT!$1:$1,'Marketing Data'!L1),IF(Table1[[#This Row],[Project]]="ყველა პროექტი",SUMIFS(REPORT!$27:$27,REPORT!$1:$1,'Marketing Data'!L1),SUMIFS(REPORT!$177:$177,REPORT!$1:$1,'Marketing Data'!L1)))) -> #VALUE! | Y1: =IF(Table1[[#This Row],[Project]]="სამგორი",SUMIFS(REPORT!$45:$45,REPORT!$1:$1,'Marketing Data'!L1),IF(Table1[[#This Row],[Project]]="ლისი",SUMIFS(REPORT!$51:$51,REPORT!$1:$1,'Marketing Data'!L1),IF(Table1[[#This Row],[Project]]="ყველა პროექტი",SUMIFS(REPORT!$3:$3,REPORT!$1:$1,'Marketing Data'!L1),SUMIFS(REPORT!$57:$57,REPORT!$1:$1,'Marketing Data'!L1)))) -> #VALUE! | Z1: =IF(Table1[[#This Row],[Project]]="ყველა პროექტი",SUMIFS($D:$D,$G:$G,"yes",$A:$A,Table1[[#This Row],[Date]],$H:$H,Table1[[#Headers],[Activity]]),SUMIFS($D:$D,$G:$G,"yes",$A:$A,Table1[[#This Row],[Date]],$C:$C,Table1[[#This Row],[Project]],$H:$H,Table1[[#Headers],[Activity]])) -> #VALUE! | AA1: =1 -> 1 | AB1: =IFERROR(Table1[[#This Row],[Impressions]]/Table1[[#This Row],[Reach]],"") | AC1: =IFERROR(Table1[[#This Row],[Facebook Costs]]/(Table1[[#This Row],[Impressions]]/1000),"") | AD1: =IFERROR(Table1[[#This Row],[Facebook Costs]]/Table1[[#This Row],[Activity]],"") | AE1: =IFERROR(Table1[[#This Row],[Facebook Costs]]/Table1[[#This Row],[Results]],"") | AF1: =IFERROR((Table1[[#This Row],[Web Marketing]]+Table1[[#This Row],[Facebook Costs]])/Table1[[#This Row],[Sales]],"") | AG1: =IFERROR(Table1[[#This Row],[FB Lead]]/Table1[[#This Row],[Activity]],"") | AH1: =IFERROR(Table1[[#This Row],[Sales]]/Table1[[#This Row],[Activity]],"") | AI1: =IFERROR(Table1[[#This Row],[Activity]]/Table1[[#This Row],[Messages Reach]],0) -> 0 | AJ1: =Table1[[#This Row],[Sales]]/Table1[[#This Row],[Lead]] -> #VALUE!
A2: Month | B2: Date | C2: Project | D2: Number | E2: Description | F2: Report Description | G2: Use in Report | H2: Report Description 2 | L2: Date | M2: Project | N2: FB Lead | O2: Lead | P2: Impressions | Q2: Reach | R2: Messages Reach | S2: Messaging Costs | T2: Facebook Costs | U2: Total Marketing Cost | V2: Web Marketing | W2: Results | X2: Stock | Y2: Sales | Z2: Activity | AA2: Count | AB2: Frequency | AC2: Cost Per Impression | AD2: Cost Per Message | AE2: Cost Per Result | AF2: Cost Per Sale | AG2: Activity to Lead Progression Rate | AH2: Activity-to-Sale Conversion Rate | AI2: Reach-to-Message Conversion Rate (%) | AJ2: Lead Conversion Rate | AS2: Average Sale | AT2: =GETPIVOTDATA("Sales",$AS$5) -> 5.0714286 | BI2: Average Lead | BJ2: =GETPIVOTDATA("Lead",$BI$5) -> 41.892857 | BY2: Average Frequency | BZ2: =GETPIVOTDATA("Frequency",$BY$5) -> 2.8476898 | CO2: Average Cost | CP2: =GETPIVOTDATA("Cost Per Impression",$CO$5) -> 2.2967244 | DF2: Average Cost | DG2: =GETPIVOTDATA("Cost Per Message",$DF$5) -> 25.469041 | DU2: Average Cost | DV2: =GETPIVOTDATA("Cost Per Sale",$DU$5) -> 859.05054 | EK2: Average % | EL2: =GETPIVOTDATA("Activity to Lead Progression Rate",$EK$5) -> 0.22148475 | EY2: Average % | EZ2: =GETPIVOTDATA("Activity-to-Sale Conversion Rate",$EY$5) -> 0.04287173 | FN2: Average % | FO2: =GETPIVOTDATA("Reach-to-Message Conversion Rate (%)",$FN$5) -> 0.00092838801 | GB2: Average % | GC2: =GETPIVOTDATA("Lead Conversion Rate",$GB$5) -> 0.12553973 | GQ2: Average cost | GR2: =GETPIVOTDATA("Total Marketing Cost",$GQ$5) -> 3162.4004 | HH2: Average Stock | HI2: =GETPIVOTDATA("Stock",$HH$5) -> 53.821429 | IC2: =GETPIVOTDATA("Cost Per Result",$IB$5) -> 1.7752885
A3: =EOMONTH(B3,0) -> 44712 | B3: 2022-05-24 13:44:19 | C3: სამგორი | D3: 1 | E3: Internet | F3: Lead | G3: Yes | L3: 45322 | M3: სამგორი | N3: 139 | O3: 208 | P3: 2269807 | Q3: 1078260 | R3: 148217 | S3: 649.89 | T3: 1819.89 | U3: 1819.89 | V3: 0 | W3: 116024 | X3: 103 | Y3: 4 | Z3: 290 | AA3: 1 | AB3: 2.1050646 | AC3: 0.80178183 | AD3: 6.2754828 | AE3: 0.015685462 | AF3: 454.9725 | AG3: 0.47931034 | AH3: 0.013793103 | AI3: 0.0019565907 | AJ3: 0.019230769
A4: 44712 | B4: 2022-05-24 17:04:05 | C4: სამგორი | D4: 1 | E4: Construction Site | F4: Lead | G4: Yes | L4: 45322 | M4: ლისი | N4: 16 | O4: 28 | P4: 2416745 | Q4: 1195220 | R4: 27028 | S4: 200 | T4: 1680 | U4: 1680 | V4: 0 | W4: 112170 | X4: 38 | Y4: 6 | Z4: 41 | AA4: 1 | AB4: 2.0220085 | AC4: 0.69514988 | AD4: 40.97561 | AE4: 0.014977267 | AF4: 280 | AG4: 0.3902439 | AH4: 0.14634146 | AI4: 0.0015169454 | AJ4: 0.21428571
A5: 44712 | B5: 2022-05-24 17:12:56 | C5: სამგორი | D5: 1 | E5: FB | F5: Lead | G5: Yes | L5: 45322 | M5: უნივერსიტეტი | N5: 37 | O5: 82 | P5: 2067422 | Q5: 1113380 | R5: 96256 | S5: 450 | T5: 1450 | U5: 1450 | V5: 0 | W5: 34874 | X5: 12 | Y5: 6 | Z5: 171 | AA5: 1 | AB5: 1.856888 | AC5: 0.70135657 | AD5: 8.4795322 | AE5: 0.041578253 | AF5: 241.66667 | AG5: 0.21637427 | AH5: 0.035087719 | AI5: 0.0017765126 | AJ5: 0.073170732 | AL5: Sum of Sales | AM5: Column Labels | AS5: Average of Sales | AT5: Column Labels | BA5: Sum of Lead | BB5: Column Labels | BI5: Average of Lead | BJ5: Column Labels | BQ5: Sum of Frequency | BR5: Column Labels | BY5: Average of Frequency | BZ5: Column Labels | CG5: Sum of Cost Per Impression | CH5: Column Labels | CO5: Average of Cost Per Impression | CP5: Column Labels | CX5: Sum of Cost Per Message | CY5: Column Labels | DF5: Average of Cost Per Message | DG5: Column Labels | DN5: Sum of Cost Per Sale | DO5: Column Labels | DU5: Average of Cost Per Sale | DV5: Column Labels | EC5: Sum of Activity to Lead Progression Rate | ED5: Column Labels | EK5: Average of Activity to Lead Progression Rate | EL5: Column Labels | ER5: Sum of Activity-to-Sale Conversion Rate | ES5: Column Labels | EY5: Average of Activity-to-Sale Conversion Rate | EZ5: Column Labels | FF5: Sum of Reach-to-Message Conversion Rate (%) | FG5: Column Labels | FN5: Average of Reach-to-Message Conversion Rate (%) | FO5: Column Labels | FU5: Sum of Lead Conversion Rate | FV5: Column Labels | GB5: Average of Lead Conversion Rate | GC5: Column Labels | GJ5: Sum of Total Marketing Cost | GK5: Column Labels | GQ5: Average of Total Marketing Cost | GR5: Column Labels | GZ5: Sum of Stock | HA5: Column Labels | HH5: Average of Stock | HI5: Column Labels | HQ5: Sum of Cost Per Result | HR5: Column Labels | IB5: Average of Cost Per Result | IC5: Column Labels
A6: 44712 | B6: 2022-05-24 18:38:14 | C6: ლისი | D6: 1 | E6: Other | F6: Lead | G6: Yes | L6: 45322 | M6: ყველა პროექტი | N6: 192 | O6: 318 | P6: 6753974 | Q6: 3386860 | R6: 271501 | S6: 1299.89 | T6: 4949.89 | U6: 4949.89 | V6: 0 | W6: 263068 | X6: 153 | Y6: 16 | Z6: 502 | AA6: 1 | AB6: 1.9941698 | AC6: 0.73288556 | AD6: 9.8603386 | AE6: 0.01881601 | AF6: 309.36813 | AG6: 0.38247012 | AH6: 0.03187251 | AI6: 0.0018489803 | AJ6: 0.050314465 | AL6: Row Labels | AM6: ლისი | AN6: Grand Total | AS6: Row Labels | AT6: ლისი | AU6: Grand Total | BA6: Row Labels | BB6: ლისი | BC6: Grand Total | BI6: Row Labels | BJ6: ლისი | BK6: Grand Total | BQ6: Row Labels | BR6: ლისი | BS6: Grand Total | BY6: Row Labels | BZ6: ლისი | CA6: Grand Total | CG6: Row Labels | CH6: ლისი | CI6: Grand Total | CO6: Row Labels | CP6: ლისი | CQ6: Grand Total | CX6: Row Labels | CY6: ლისი | CZ6: Grand Total | DF6: Row Labels | DG6: ლისი | DH6: Grand Total | DN6: Row Labels | DO6: ლისი | DP6: Grand Total | DU6: Row Labels | DV6: ლისი | DW6: Grand Total | EC6: Row Labels | ED6: ლისი | EE6: Grand Total | EK6: Row Labels | EL6: ლისი | EM6: Grand Total | ER6: Row Labels | ES6: ლისი | ET6: Grand Total | EY6: Row Labels | EZ6: ლისი | FA6: Grand Total | FF6: Row Labels | FG6: ლისი | FH6: Grand Total | FN6: Row Labels | FO6: ლისი | FP6: Grand Total | FU6: Row Labels | FV6: ლისი | FW6: Grand Total | GB6: Row Labels | GC6: ლისი | GD6: Grand Total | GJ6: Row Labels | GK6: ლისი | GL6: Grand Total | GQ6: Row Labels | GR6: ლისი | GS6: Grand Total | GZ6: Row Labels | HA6: ლისი | HB6: Grand Total | HH6: Row Labels | HI6: ლისი | HJ6: Grand Total | HQ6: Row Labels | HR6: ლისი | HS6: Grand Total | IB6: Row Labels | IC6: ლისი | ID6: Grand Total | IL6: Total Costs | IM6: =GETPIVOTDATA("Total Marketing Cost",$GJ$5) -> 88547.21 | IN6: =TEXT(IM6,"$ ##,###.00") -> $ 88,547.21
A7: 44712 | B7: 2022-05-24 17:25:21 | D7: 1 | E7: Co-worker / Acquaintance | F7: Lead | G7: No | L7: 45351 | M7: სამგორი | N7: 180 | O7: 289 | P7: 3627430 | Q7: 1646560 | R7: 0 | S7: 0 | T7: 2500 | U7: 2500 | V7: 0 | W7: 37029 | X7: 155 | Y7: 12 | Z7: 0 | AA7: 1 | AB7: 2.2030354 | AC7: 0.68919318 | AE7: 0.067514651 | AF7: 208.33333 | AI7: 0 | AJ7: 0.041522491 | AL7: 2024 | AM7: 47 | AN7: 47 | AS7: 2024 | AT7: 3.9166667 | AU7: 3.9166667 | BA7: 2024 | BB7: 540 | BC7: 540 | BI7: 2024 | BJ7: 45 | BK7: 45 | BQ7: 2024 | BR7: 29.27275 | BS7: 29.27275 | BY7: 2024 | BZ7: 2.4393958 | CA7: 2.4393958 | CG7: 2024 | CH7: 30.775078 | CI7: 30.775078 | CO7: 2024 | CP7: 2.5645899 | CQ7: 2.5645899 | CX7: 2024 | CY7: 290.85013 | CZ7: 290.85013 | DF7: 2024 | DG7: 24.237511 | DH7: 24.237511 | DN7: 2024 | DO7: 7661.5239 | DP7: 7661.5239 | DU7: 2024 | DV7: 696.50218 | DW7: 696.50218 | EC7: 2024 | ED7: 3.3406657 | EE7: 3.3406657 | EK7: 2024 | EL7: 0.27838881 | EM7: 0.27838881 | ER7: 2024 | ES7: 0.45786391 | ET7: 0.45786391 | EY7: 2024 | EZ7: 0.038155326 | FA7: 0.038155326 | FF7: 2024 | FG7: 0.014949459 | FH7: 0.014949459 | FN7: 2024 | FO7: 0.0012457882 | FP7: 0.0012457882 | FU7: 2024 | FV7: 1.0766284 | FW7: 1.0766284 | GB7: 2024 | GC7: 0.089719032 | GD7: 0.089719032 | GJ7: 2024 | GK7: 22993.13 | GL7: 22993.13 | GQ7: 2024 | GR7: 1916.0942 | GS7: 1916.0942 | GZ7: 2024 | HA7: 558 | HB7: 558 | HH7: 2024 | HI7: 46.5 | HJ7: 46.5 | HQ7: 2024 | HR7: 22.680694 | HS7: 22.680694 | IB7: 2024 | IC7: 1.8900578 | ID7: 1.8900578 | IL7: Total Sales | IM7: =GETPIVOTDATA("Sales",$AL$5) -> 142 | IN7: =TEXT(IM7,"##,###") -> 142
A8: 44712 | B8: 2022-05-24 18:12:47 | C8: სამგორი | D8: 1 | E8: Co-worker / Acquaintance | F8: Lead | G8: Yes | L8: 45351 | M8: ლისი | N8: 25 | O8: 52 | P8: 1801206 | Q8: 851432 | R8: 35793 | S8: 300 | T8: 1600 | U8: 1600 | V8: 0 | W8: 18187 | X8: 35 | Y8: 3 | Z8: 92 | AA8: 1 | AB8: 2.1155019 | AC8: 0.88829373 | AD8: 17.391304 | AE8: 0.087974927 | AF8: 533.33333 | AG8: 0.27173913 | AH8: 0.032608696 | AI8: 0.002570335 | AJ8: 0.057692308 | AL8: Jan | AM8: 6 | AN8: 6 | AS8: 2025 | AT8: 6.3333333 | AU8: 6.3333333 | BA8: Jan | BB8: 28 | BC8: 28 | BI8: 2025 | BJ8: 41.166667 | BK8: 41.166667 | BQ8: Jan | BR8: 2.0220085 | BS8: 2.0220085 | BY8: 2025 | BZ8: 2.7162749 | CA8: 2.7162749 | CG8: Jan | CH8: 0.69514988 | CI8: 0.69514988 | CO8: 2025 | CP8: 2.52137 | CQ8: 2.52137 | CX8: Jan | CY8: 40.97561 | CZ8: 40.97561 | DF8: 2025 | DG8: 23.074847 | DH8: 23.074847 | DN8: Jan | DO8: 280 | DP8: 280 | DU8: 2025 | DV8: 673.2507 | DW8: 673.2507 | EC8: Jan | ED8: 0.3902439 | EE8: 0.3902439 | EK8: 2025 | EL8: 0.18600385 | EM8: 0.18600385 | ER8: Jan | ES8: 0.14634146 | ET8: 0.14634146 | EY8: 2025 | EZ8: 0.051021769 | FA8: 0.051021769 | FF8: Jan | FG8: 0.0015169454 | FH8: 0.0015169454 | FN8: 2025 | FO8: 0.00074732294 | FP8: 0.00074732294 | FU8: Jan | FV8: 0.21428571 | FW8: 0.21428571 | GB8: 2025 | GC8: 0.15630685 | GD8: 0.15630685 | GJ8: Jan | GK8: 1680 | GL8: 1680 | GQ8: 2025 | GR8: 3132.2483 | GS8: 3132.2483 | GZ8: Jan | HA8: 38 | HB8: 38 | HH8: 2025 | HI8: 55.833333 | HJ8: 55.833333 | HQ8: Jan | HR8: 0.014977267 | HS8: 0.014977267 | IB8: 2025 | IC8: 2.244366 | ID8: 2.244366 | IL8: Total Leads
A9: 44712 | B9: 2022-05-25 12:58:32 | C9: ლისი | D9: 1 | E9: Existing customer | F9: Lead | G9: Yes | L9: 45351 | M9: უნივერსიტეტი | N9: 52 | O9: 104 | P9: 2745106 | Q9: 1351882 | R9: 77451 | S9: 300 | T9: 1700 | U9: 1700 | V9: 0 | W9: 14404 | X9: 23 | Y9: 6 | Z9: 201 | AA9: 1 | AB9: 2.0305811 | AC9: 0.61928392 | AD9: 8.4577114 | AE9: 0.11802277 | AF9: 283.33333 | AG9: 0.25870647 | AH9: 0.029850746 | AI9: 0.0025951892 | AJ9: 0.057692308 | AL9: Feb | AM9: 3 | AN9: 3 | AS9: 2026 | AT9: 4.75 | AU9: 4.75 | BA9: Feb | BB9: 52 | BC9: 52 | BI9: 2026 | BJ9: 34.75 | BK9: 34.75 | BQ9: Feb | BR9: 2.1155019 | BS9: 2.1155019 | BY9: 2026 | BZ9: 4.4668166 | CA9: 4.4668166 | CG9: Feb | CH9: 0.88829373 | CI9: 0.88829373 | CO9: 2026 | CP9: 0.81919123 | CQ9: 0.81919123 | CX9: Feb | CY9: 17.391304 | CZ9: 17.391304 | DF9: 2026 | DG9: 36.346213 | DH9: 36.346213 | DN9: Feb | DO9: 533.33333 | DP9: 533.33333 | DU9: 2026 | DV9: 1817.0081 | DW9: 1817.0081 | EC9: Feb | ED9: 0.27173913 | EE9: 0.27173913 | EK9: 2026 | EL9: 0.15721527 | EM9: 0.15721527 | ER9: Feb | ES9: 0.032608696 | ET9: 0.032608696 | EY9: 2026 | EZ9: 0.032570828 | FA9: 0.032570828 | FF9: Feb | FG9: 0.002570335 | FH9: 0.002570335 | FN9: 2026 | FO9: 0.00051938263 | FP9: 0.00051938263 | FU9: Feb | FV9: 0.057692308 | FW9: 0.057692308 | GB9: 2026 | GC9: 0.14070048 | GD9: 0.14070048 | GJ9: Feb | GK9: 1600 | GL9: 1600 | GQ9: 2026 | GR9: 6991.775 | GS9: 6991.775 | GZ9: Feb | HA9: 35 | HB9: 35 | HH9: 2026 | HI9: 69.75 | HJ9: 69.75 | HQ9: Feb | HR9: 0.087974927 | HS9: 0.087974927 | IB9: 2026 | IC9: 0.023748158 | ID9: 0.023748158
A10: 44712 | B10: 2022-05-25 11:02:13 | C10: სამგორი | D10: 1 | E10: Construction Site | F10: Lead | G10: Yes | L10: 45351 | M10: ყველა პროექტი | N10: 257 | O10: 445 | P10: 8173742 | Q10: 3849874 | R10: 113244 | S10: 600 | T10: 5800 | U10: 5800 | V10: 0 | W10: 69620 | X10: 213 | Y10: 21 | Z10: 293 | AA10: 1 | AB10: 2.1231194 | AC10: 0.70958932 | AD10: 19.795222 | AE10: 0.083309394 | AF10: 276.19048 | AG10: 0.87713311 | AH10: 0.071672355 | AI10: 0.0025873335 | AJ10: 0.047191011 | AL10: Mar | AM10: 1 | AN10: 1 | AS10: Grand Total | AT10: 5.0714286 | AU10: 5.0714286 | BA10: Mar | BB10: 37 | BC10: 37 | BI10: Grand Total | BJ10: 41.892857 | BK10: 41.892857 | BQ10: Mar | BR10: 2.1731758 | BS10: 2.1731758 | BY10: Grand Total | BZ10: 2.8476898 | CA10: 2.8476898 | CG10: Mar | CH10: 0.72654105 | CI10: 0.72654105 | CO10: Grand Total | CP10: 2.2967244 | CQ10: 2.2967244 | CX10: Mar | CY10: 134.41357 | CZ10: 134.41357 | DF10: Grand Total | DG10: 25.469041 | DH10: 25.469041 | DN10: Mar | DO10: 1881.79 | DP10: 1881.79 | DU10: Grand Total | DV10: 859.05054 | DW10: 859.05054 | EC10: Mar | ED10: 1.3571429 | EE10: 1.3571429 | EK10: Grand Total | EL10: 0.22148475 | EM10: 0.22148475 | ER10: Mar | ES10: 0.071428571 | ET10: 0.071428571 | EY10: Grand Total | EZ10: 0.04287173 | FA10: 0.04287173 | FF10: Mar | FG10: 0.0016368526 | FH10: 0.0016368526 | FN10: Grand Total | FO10: 0.00092838801 | FP10: 0.00092838801 | FU10: Mar | FV10: 0.027027027 | FW10: 0.027027027 | GB10: Grand Total | GC10: 0.12553973 | GD10: 0.12553973 | GJ10: Mar | GK10: 1881.79 | GL10: 1881.79 | GQ10: Grand Total | GR10: 3162.4004 | GS10: 3162.4004 | GZ10: Mar | HA10: 36 | HB10: 36 | HH10: Grand Total | HI10: 53.821429 | HJ10: 53.821429 | HQ10: Mar | HR10: 0.08435494 | HS10: 0.08435494 | IB10: Grand Total | IC10: 1.7752885 | ID10: 1.7752885
A11: 44712 | B11: 2022-05-25 11:55:00 | C11: სამგორი | D11: 1 | E11: Existing customer | F11: Lead | G11: Yes | L11: 45382 | M11: სამგორი | N11: 178 | O11: 230 | P11: 2867076 | Q11: 1247318 | R11: 42116 | S11: 246.95 | T11: 2396.95 | U11: 2396.95 | V11: 0 | W11: 26319 | X11: 141 | Y11: 17 | Z11: 118 | AA11: 1 | AB11: 2.2985927 | AC11: 0.83602597 | AD11: 20.313136 | AE11: 0.091072989 | AF11: 140.99706 | AG11: 1.5084746 | AH11: 0.1440678 | AI11: 0.0028017855 | AJ11: 0.073913043 | AL11: Apr | AM11: 4 | AN11: 4 | BA11: Apr | BB11: 62 | BC11: 62 | BQ11: Apr | BR11: 2.6590571 | BS11: 2.6590571 | CG11: Apr | CH11: 2.9731757 | CI11: 2.9731757 | CX11: Apr | CY11: 8.5281613 | CZ11: 8.5281613 | DN11: Apr | DO11: 660.9325 | DP11: 660.9325 | EC11: Apr | ED11: 0.12258065 | EE11: 0.12258065 | ER11: Apr | ES11: 0.012903226 | ET11: 0.012903226 | FF11: Apr | FG11: 0.001884911 | FH11: 0.001884911 | FU11: Apr | FV11: 0.064516129 | FW11: 0.064516129 | GJ11: Apr | GK11: 2643.73 | GL11: 2643.73 | GZ11: Apr | HA11: 62 | HB11: 62 | HQ11: Apr | HR11: 0.035360057 | HS11: 0.035360057
A12: 44712 | B12: 2022-05-25 12:43:39 | C12: სამგორი | D12: 1 | E12: Construction Site | F12: Lead | G12: Yes | L12: 45382 | M12: ლისი | N12: 19 | O12: 37 | P12: 2590067 | Q12: 1191835 | R12: 8553 | S12: 131.79 | T12: 1881.79 | U12: 1881.79 | V12: 0 | W12: 22308 | X12: 36 | Y12: 1 | Z12: 14 | AA12: 1 | AB12: 2.1731758 | AC12: 0.72654105 | AD12: 134.41357 | AE12: 0.08435494 | AF12: 1881.79 | AG12: 1.3571429 | AH12: 0.071428571 | AI12: 0.0016368526 | AJ12: 0.027027027 | AL12: May | AM12: 1 | AN12: 1 | BA12: May | BB12: 43 | BC12: 43 | BQ12: May | BR12: 2.7285118 | BS12: 2.7285118 | CG12: May | CH12: 2.81883 | CI12: 2.81883 | CX12: May | CY12: 9.5045578 | CZ12: 9.5045578 | DN12: May | DO12: 1397.17 | DP12: 1397.17 | EC12: May | ED12: 0.20408163 | EE12: 0.20408163 | ER12: May | ES12: 0.0068027211 | ET12: 0.0068027211 | FF12: May | FG12: 0.0010912411 | FH12: 0.0010912411 | FU12: May | FV12: 0.023255814 | FW12: 0.023255814 | GJ12: May | GK12: 1397.17 | GL12: 1397.17 | GZ12: May | HA12: 61 | HB12: 61 | HQ12: May | HR12: 0.44795447 | HS12: 0.44795447
A13: 44712 | B13: 2022-05-25 15:31:46 | C13: სამგორი | D13: 1 | E13: FB | F13: Lead | G13: Yes | L13: 45382 | M13: უნივერსიტეტი | N13: 65 | O13: 99 | P13: 1774290 | Q13: 793109 | R13: 76232 | S13: 858.17 | T13: 2808.17 | U13: 2808.17 | V13: 0 | W13: 140742 | X13: 21 | Y13: 2 | Z13: 205 | AA13: 1 | AB13: 2.2371326 | AC13: 1.5827007 | AD13: 13.69839 | AE13: 0.019952608 | AF13: 1404.085 | AG13: 0.31707317 | AH13: 0.0097560976 | AI13: 0.0026891594 | AJ13: 0.02020202 | AL13: Jun | AM13: 2 | AN13: 2 | BA13: Jun | BB13: 29 | BC13: 29 | BQ13: Jun | BR13: 2.900993 | BS13: 2.900993 | CG13: Jun | CH13: 2.8828313 | CI13: 2.8828313 | CX13: Jun | CY13: 11.418121 | CZ13: 11.418121 | DN13: Jun | DO13: 850.65 | DP13: 850.65 | EC13: Jun | ED13: 0.11409396 | EE13: 0.11409396 | ER13: Jun | ES13: 0.013422819 | ET13: 0.013422819 | FF13: Jun | FG13: 0.00084315601 | FH13: 0.00084315601 | FU13: Jun | FV13: 0.068965517 | FW13: 0.068965517 | GJ13: Jun | GK13: 1701.3 | GL13: 1701.3 | GZ13: Jun | HA13: 59 | HB13: 59 | HQ13: Jun | HR13: 2.4514409 | HS13: 2.4514409
A14: 44712 | B14: 2022-05-25 11:53:26 | C14: სამგორი | D14: 1 | E14: FB | F14: Lead | G14: Yes | L14: 45382 | M14: ყველა პროექტი | N14: 262 | O14: 366 | P14: 7231433 | Q14: 3232262 | R14: 126901 | S14: 1236.91 | T14: 7086.91 | U14: 7086.91 | V14: 0 | W14: 189369 | X14: 198 | Y14: 20 | Z14: 337 | AA14: 1 | AB14: 2.237267 | AC14: 0.98001461 | AD14: 21.029407 | AE14: 0.037423813 | AF14: 354.3455 | AG14: 0.77744807 | AH14: 0.059347181 | AI14: 0.0026556134 | AJ14: 0.054644809 | AL14: Jul | AM14: 10 | AN14: 10 | BA14: Jul | BB14: 48 | BC14: 48 | BQ14: Jul | BR14: 2.299214 | BS14: 2.299214 | CG14: Jul | CH14: 2.0368269 | CI14: 2.0368269 | CX14: Jul | CY14: 15.339 | CZ14: 15.339 | DN14: Jul | DO14: 245.424 | DP14: 245.424 | EC14: Jul | ED14: 0.175 | EE14: 0.175 | ER14: Jul | ES14: 0.0625 | ET14: 0.0625 | FF14: Jul | FG14: 0.00060855707 | FH14: 0.00060855707 | FU14: Jul | FV14: 0.20833333 | FW14: 0.20833333 | GJ14: Jul | GK14: 2454.24 | GL14: 2454.24 | GZ14: Jul | HA14: 49 | HB14: 49 | HQ14: Jul | HR14: 0.36342959 | HS14: 0.36342959
A15: 44712 | B15: 2022-05-25 12:13:53 | C15: სამგორი | D15: 1 | E15: FB | F15: Lead | G15: Yes | L15: 45412 | M15: სამგორი | N15: 189 | O15: 246 | P15: 933182 | Q15: 313046 | R15: 232093 | S15: 1950 | T15: 2081 | U15: 2081 | V15: 0 | W15: 1763 | X15: 122 | Y15: 19 | Z15: 755 | AA15: 1 | AB15: 2.980974 | AC15: 2.2300044 | AD15: 2.7562914 | AE15: 1.1803744 | AF15: 109.52632 | AG15: 0.25033113 | AH15: 0.025165563 | AI15: 0.0032530063 | AJ15: 0.077235772 | AL15: Aug | AM15: 5 | AN15: 5 | BA15: Aug | BB15: 47 | BC15: 47 | BQ15: Aug | BR15: 2.3241671 | BS15: 2.3241671 | CG15: Aug | CH15: 3.5616161 | CI15: 3.5616161 | CX15: Aug | CY15: 12.284485 | CZ15: 12.284485 | DN15: Aug | DO15: 334.138 | DP15: 334.138 | EC15: Aug | ED15: 0.13235294 | EE15: 0.13235294 | ER15: Aug | ES15: 0.036764706 | ET15: 0.036764706 | FF15: Aug | FG15: 0.00075934808 | FH15: 0.00075934808 | FU15: Aug | FV15: 0.10638298 | FW15: 0.10638298 | GJ15: Aug | GK15: 1670.69 | GL15: 1670.69 | GZ15: Aug | HA15: 44 | HB15: 44 | HQ15: Aug | HR15: 0.025006586 | HS15: 0.025006586
A16: 44712 | B16: 2022-05-25 12:15:15 | C16: სამგორი | D16: 1 | E16: FB | F16: Lead | G16: Yes | L16: 45412 | M16: ლისი | N16: 38 | O16: 62 | P16: 889194 | Q16: 334402 | R16: 164464 | S16: 2093.73 | T16: 2643.73 | U16: 2643.73 | V16: 0 | W16: 74766 | X16: 62 | Y16: 4 | Z16: 310 | AA16: 1 | AB16: 2.6590571 | AC16: 2.9731757 | AD16: 8.5281613 | AE16: 0.035360057 | AF16: 660.9325 | AG16: 0.12258065 | AH16: 0.012903226 | AI16: 0.001884911 | AJ16: 0.064516129 | AL16: Sep | AM16: 9 | AN16: 9 | BA16: Sep | BB16: 58 | BC16: 58 | BQ16: Sep | BR16: 2.215693 | BS16: 2.215693 | CG16: Sep | CH16: 4.0069498 | CI16: 4.0069498 | CX16: Sep | CY16: 9.8688745 | CZ16: 9.8688745 | DN16: Sep | DO16: 253.30111 | DP16: 253.30111 | EC16: Sep | ED16: 0.13852814 | EE16: 0.13852814 | ER16: Sep | ES16: 0.038961039 | ET16: 0.038961039 | FF16: Sep | FG16: 0.00097584055 | FH16: 0.00097584055 | FU16: Sep | FV16: 0.15517241 | FW16: 0.15517241 | GJ16: Sep | GK16: 2279.71 | GL16: 2279.71 | GZ16: Sep | HA16: 35 | HB16: 35 | HQ16: Sep | HR16: 0.036475944 | HS16: 0.036475944
A17: 44712 | B17: 2022-05-25 12:26:16 | C17: სამგორი | D17: 1 | E17: FB | F17: Lead | G17: Yes | L17: 45412 | M17: უნივერსიტეტი | N17: 66 | O17: 111 | P17: 1591956 | Q17: 719452 | R17: 537947 | S17: 2148.64 | T17: 2998.64 | U17: 2998.64 | V17: 0 | W17: 118661 | X17: 143 | Y17: 10 | Z17: 606 | AA17: 1 | AB17: 2.2127341 | AC17: 1.8836199 | AD17: 4.9482508 | AE17: 0.025270645 | AF17: 299.864 | AG17: 0.10891089 | AH17: 0.01650165 | AI17: 0.001126505 | AJ17: 0.09009009 | AL17: Oct | AM17: 0 | AN17: 0 | BA17: Oct | BB17: 56 | BC17: 56 | BQ17: Oct | BR17: 2.4641534 | BS17: 2.4641534 | CG17: Oct | CH17: 3.0808979 | CI17: 3.0808979 | CX17: Oct | CY17: 9.9327727 | CZ17: 9.9327727 | DN17: Oct | DO17: 0 | DP17: 0 | EC17: Oct | ED17: 0.11818182 | EE17: 0.11818182 | ER17: Oct | ES17: 0 | ET17: 0 | FF17: Oct | FG17: 0.00099242151 | FH17: 0.00099242151 | FU17: Oct | FV17: 0 | FW17: 0 | GJ17: Oct | GK17: 2185.21 | GL17: 2185.21 | GZ17: Oct | HA17: 35 | HB17: 35 | HQ17: Oct | HR17: 1.3963003 | HS17: 1.3963003
A18: 44712 | B18: 2022-05-25 12:51:12 | C18: სამგორი | D18: 1 | E18: FB | F18: Lead | G18: Yes | L18: 45412 | M18: ყველა პროექტი | N18: 293 | O18: 419 | P18: 3414332 | Q18: 1366900 | R18: 934504 | S18: 6192.37 | T18: 7723.37 | U18: 7723.37 | V18: 0 | W18: 195190 | X18: 327 | Y18: 33 | Z18: 1671 | AA18: 1 | AB18: 2.4978652 | AC18: 2.2620442 | AD18: 4.6220048 | AE18: 0.039568472 | AF18: 234.04152 | AG18: 0.17534411 | AH18: 0.019748654 | AI18: 0.0017881143 | AJ18: 0.07875895 | AL18: Nov | AM18: 4 | AN18: 4 | BA18: Nov | BB18: 54 | BC18: 54 | BQ18: Nov | BR18: 2.5888548 | BS18: 2.5888548 | CG18: Nov | CH18: 3.4945238 | CI18: 3.4945238 | CX18: Nov | CY18: 12.277427 | CZ18: 12.277427 | DN18: Nov | DO18: 524.86 | DP18: 524.86 | EC18: Nov | ED18: 0.23391813 | EE18: 0.23391813 | ER18: Nov | ES18: 0.023391813 | ET18: 0.023391813 | FF18: Nov | FG18: 0.00094388572 | FH18: 0.00094388572 | FU18: Nov | FV18: 0.074074074 | FW18: 0.074074074 | GJ18: Nov | GK18: 2099.44 | GL18: 2099.44 | GZ18: Nov | HA18: 53 | HB18: 53 | HQ18: Nov | HR18: 8.8211765 | HS18: 8.8211765
A19: 44712 | B19: 2022-05-25 12:56:21 | C19: სამგორი | D19: 1 | E19: Internet | F19: Lead | G19: Yes | L19: 45443 | M19: სამგორი | N19: 113 | O19: 175 | P19: 1000178 | Q19: 443620 | R19: 443620 | S19: 1750 | T19: 1750 | U19: 1750 | V19: 0 | W19: 561 | X19: 167 | Y19: 11 | Z19: 561 | AA19: 1 | AB19: 2.2545828 | AC19: 1.7496886 | AD19: 3.1194296 | AE19: 3.1194296 | AF19: 159.09091 | AG19: 0.20142602 | AH19: 0.019607843 | AI19: 0.0012645958 | AJ19: 0.062857143 | AL19: Dec | AM19: 2 | AN19: 2 | BA19: Dec | BB19: 26 | BC19: 26 | BQ19: Dec | BR19: 2.7814194 | BS19: 2.7814194 | CG19: Dec | CH19: 3.6094423 | CI19: 3.6094423 | CX19: Dec | CY19: 8.916242 | CZ19: 8.916242 | DN19: Dec | DO19: 699.925 | DP19: 699.925 | EC19: Dec | ED19: 0.082802548 | EE19: 0.082802548 | ER19: Dec | ES19: 0.012738854 | ET19: 0.012738854 | FF19: Dec | FG19: 0.0011259646 | FH19: 0.0011259646 | FU19: Dec | FV19: 0.076923077 | FW19: 0.076923077 | GJ19: Dec | GK19: 1399.85 | GL19: 1399.85 | GZ19: Dec | HA19: 51 | HB19: 51 | HQ19: Dec | HR19: 8.916242 | HS19: 8.916242
A20: 44712 | B20: 2022-05-25 14:48:25 | C20: სამგორი | D20: 1 | E20: Co-worker / Acquaintance | F20: Lead | G20: Yes | L20: 45443 | M20: ლისი | N20: 30 | O20: 43 | P20: 495656 | Q20: 181658 | R20: 134709 | S20: 1297.17 | T20: 1397.17 | U20: 1397.17 | V20: 0 | W20: 3119 | X20: 61 | Y20: 1 | Z20: 147 | AA20: 1 | AB20: 2.7285118 | AC20: 2.81883 | AD20: 9.5045578 | AE20: 0.44795447 | AF20: 1397.17 | AG20: 0.20408163 | AH20: 0.0068027211 | AI20: 0.0010912411 | AJ20: 0.023255814 | AL20: 2025 | AM20: 76 | AN20: 76 | BA20: 2025 | BB20: 494 | BC20: 494 | BQ20: 2025 | BR20: 32.595299 | BS20: 32.595299 | CG20: 2025 | CH20: 30.25644 | CI20: 30.25644 | CX20: 2025 | CY20: 276.89816 | CZ20: 276.89816 | DN20: 2025 | DO20: 7405.7577 | DP20: 7405.7577 | EC20: 2025 | ED20: 2.2320462 | EE20: 2.2320462 | ER20: 2025 | ES20: 0.61226122 | ET20: 0.61226122 | FF20: 2025 | FG20: 0.0089678752 | FH20: 0.0089678752 | FU20: 2025 | FV20: 1.8756822 | FW20: 1.8756822 | GJ20: 2025 | GK20: 37586.98 | GL20: 37586.98 | GZ20: 2025 | HA20: 670 | HB20: 670 | HQ20: 2025 | HR20: 26.932392 | HS20: 26.932392
A21: 44712 | B21: 2022-05-25 15:05:21 | C21: სამგორი | D21: 1 | E21: FB | F21: Lead | G21: Yes | L21: 45443 | M21: უნივერსიტეტი | N21: 52 | O21: 76 | P21: 1394324 | Q21: 669946 | R21: 601236 | S21: 1550 | T21: 1650 | U21: 1650 | V21: 0 | W21: 1990 | X21: 137 | Y21: 6 | Z21: 499 | AA21: 1 | AB21: 2.0812483 | AC21: 1.1833691 | AD21: 3.3066132 | AE21: 0.82914573 | AF21: 275 | AG21: 0.10420842 | AH21: 0.012024048 | AI21: 0.00082995696 | AJ21: 0.078947368 | AL21: Jan | AM21: 0 | AN21: 0 | BA21: Jan | BB21: 42 | BC21: 42 | BQ21: Jan | BR21: 2.374973 | BS21: 2.374973 | CG21: Jan | CH21: 2.0978963 | CI21: 2.0978963 | CX21: Jan | CY21: 8.9022156 | CZ21: 8.9022156 | DN21: Jan | DO21: 0 | DP21: 0 | EC21: Jan | ED21: 0.095808383 | EE21: 0.095808383 | ER21: Jan | ES21: 0 | ET21: 0 | FF21: Jan | FG21: 0.001225868 | FH21: 0.001225868 | FU21: Jan | FV21: 0 | FW21: 0 | GJ21: Jan | GK21: 2973.34 | GL21: 2973.34 | GZ21: Jan | HA21: 51 | HB21: 51 | HQ21: Jan | HR21: 0.13306512 | HS21: 0.13306512
A22: 44712 | B22: 2022-05-25 15:59:43 | C22: სამგორი | D22: 1 | E22: Existing customer | F22: Lead | G22: Yes | L22: 45443 | M22: ყველა პროექტი | N22: 195 | O22: 294 | P22: 2890158 | Q22: 1295224 | R22: 1179565 | S22: 4597.17 | T22: 4797.17 | U22: 4797.17 | V22: 0 | W22: 5670 | X22: 365 | Y22: 18 | Z22: 1207 | AA22: 1 | AB22: 2.2313963 | AC22: 1.6598297 | AD22: 3.9744573 | AE22: 0.84606173 | AF22: 266.50944 | AG22: 0.16155758 | AH22: 0.014913007 | AI22: 0.0010232586 | AJ22: 0.06122449 | AL22: Feb | AM22: 2 | AN22: 2 | BA22: Feb | BB22: 44 | BC22: 44 | BQ22: Feb | BR22: 2.2089861 | BS22: 2.2089861 | CG22: Feb | CH22: 3.346819 | CI22: 3.346819 | CX22: Feb | CY22: 9.668087 | CZ22: 9.668087 | DN22: Feb | DO22: 1111.83 | DP22: 1111.83 | EC22: Feb | ED22: 0.14347826 | EE22: 0.14347826 | ER22: Feb | ES22: 0.0086956522 | ET22: 0.0086956522 | FF22: Feb | FG22: 0.00076468867 | FH22: 0.00076468867 | FU22: Feb | FV22: 0.045454545 | FW22: 0.045454545 | GJ22: Feb | GK22: 2223.66 | GL22: 2223.66 | GZ22: Feb | HA22: 49 | HB22: 49 | HQ22: Feb | HR22: 9.668087 | HS22: 9.668087
... A38: 44712 | B38: 2022-05-27 17:39:51 | C38: სამგორი | D38: 1 | E38: Construction Site | F38: Lead | G38: Yes | L38: 45565 | M38: ყველა პროექტი | N38: 164 | O38: 262 | P38: 1294283 | Q38: 520284 | R38: 443592 | S38: 3781.82 | T38: 4631.73 | U38: 4631.73 | V38: 0 | W38: 212746 | X38: 286 | Y38: 39 | Z38: 764 | AA38: 1 | AB38: 2.4876471 | AC38: 3.5786068 | AD38: 6.0624738 | AE38: 0.021771173 | AF38: 118.76231 | AG38: 0.21465969 | AH38: 0.05104712 | AI38: 0.0017223034 | AJ38: 0.14885496 | AL38: Grand Total | AM38: 142 | AN38: 142 | BA38: Grand Total | BB38: 1173 | BC38: 1173 | BQ38: Grand Total | BR38: 79.735315 | BS38: 79.735315 | CG38: Grand Total | CH38: 64.308284 | CI38: 64.308284 | CX38: Grand Total | CY38: 713.13314 | CZ38: 713.13314 | DN38: Grand Total | DO38: 22335.314 | DP38: 22335.314 | EC38: Grand Total | ED38: 6.201573 | EE38: 6.201573 | ER38: Grand Total | ES38: 1.2004084 | ET38: 1.2004084 | FF38: Grand Total | FG38: 0.025994864 | FH38: 0.025994864 | FU38: Grand Total | FV38: 3.5151125 | FW38: 3.5151125 | GJ38: Grand Total | GK38: 88547.21 | GL38: 88547.21 | GZ38: Grand Total | HA38: 1507 | HB38: 1507 | HQ38: Grand Total | HR38: 49.708078 | HS38: 49.708078
A39: 44712 | B39: 2022-05-27 14:51:08 | C39: სამგორი | D39: 1 | E39: FB | F39: Lead | G39: Yes | L39: 45596 | M39: სამგორი | N39: 143 | O39: 182 | P39: 841836 | Q39: 327410 | R39: 251938 | S39: 1950 | T39: 2149.96 | U39: 2149.96 | V39: 0 | W39: 2145 | X39: 131 | Y39: 27 | Z39: 649 | AA39: 1 | AB39: 2.5711982 | AC39: 2.5538941 | AD39: 3.3127273 | AE39: 1.0023124 | AF39: 79.628148 | AG39: 0.22033898 | AH39: 0.041602465 | AI39: 0.0025760306 | AJ39: 0.14835165
A40: 44712 | B40: 2022-05-27 14:52:05 | C40: სამგორი | D40: 1 | E40: FB | F40: Lead | G40: Yes | L40: 45596 | M40: ლისი | N40: 26 | O40: 56 | P40: 709277 | Q40: 287838 | R40: 221680 | S40: 1985.23 | T40: 2185.21 | U40: 2185.21 | V40: 0 | W40: 1565 | X40: 35 | Y40: 0 | Z40: 220 | AA40: 1 | AB40: 2.4641534 | AC40: 3.0808979 | AD40: 9.9327727 | AE40: 1.3963003 | AG40: 0.11818182 | AH40: 0 | AI40: 0.00099242151 | AJ40: 0
A41: 44712 | B41: 2022-05-27 15:34:08 | C41: სამგორი | D41: 1 | E41: Existing customer | F41: Lead | G41: Yes | L41: 45596 | M41: უნივერსიტეტი | N41: 55 | O41: 94 | P41: 771934 | Q41: 315608 | R41: 274477 | S41: 1799.99 | T41: 2079.82 | U41: 2079.82 | V41: 0 | W41: 11503 | X41: 78 | Y41: 15 | Z41: 485 | AA41: 1 | AB41: 2.4458632 | AC41: 2.6942977 | AD41: 4.2882887 | AE41: 0.18080675 | AF41: 138.65467 | AG41: 0.11340206 | AH41: 0.030927835 | AI41: 0.0017669969 | AJ41: 0.15957447
A42: 44712 | B42: 2022-05-28 12:26:23 | C42: სამგორი | D42: 1 | E42: Construction Site | F42: Lead | G42: Yes | L42: 45596 | M42: ყველა პროექტი | N42: 224 | O42: 332 | P42: 2323047 | Q42: 930856 | R42: 748095 | S42: 5735.22 | T42: 6414.99 | U42: 6414.99 | V42: 0 | W42: 15213 | X42: 244 | Y42: 42 | Z42: 1354 | AA42: 1 | AB42: 2.495603 | AC42: 2.7614551 | AD42: 4.7378065 | AE42: 0.42167817 | AF42: 152.73786 | AG42: 0.16543575 | AH42: 0.031019202 | AI42: 0.0018099306 | AJ42: 0.12650602
A43: 44712 | B43: 2022-05-28 12:28:14 | C43: სამგორი | D43: 1 | E43: FB | F43: Lead | G43: Yes | L43: 45626 | M43: სამგორი | N43: 153 | O43: 185 | P43: 720837 | Q43: 247760 | R43: 225900 | S43: 1699.32 | T43: 1799.16 | U43: 1799.16 | V43: 0 | W43: 1337 | X43: 99 | Y43: 32 | Z43: 557 | AA43: 1 | AB43: 2.9094164 | AC43: 2.4959318 | AD43: 3.2300898 | AE43: 1.3456694 | AF43: 56.22375 | AG43: 0.27468582 | AH43: 0.057450628 | AI43: 0.0024656928 | AJ43: 0.17297297
A44: 44712 | B44: 2022-05-28 12:38:54 | C44: სამგორი | D44: 1 | E44: Construction Site | F44: Lead | G44: Yes | L44: 45626 | M44: ლისი | N44: 40 | O44: 54 | P44: 600780 | Q44: 232064 | R44: 181166 | S44: 1749.44 | T44: 2099.44 | U44: 2099.44 | V44: 0 | W44: 238 | X44: 53 | Y44: 4 | Z44: 171 | AA44: 1 | AB44: 2.5888548 | AC44: 3.4945238 | AD44: 12.277427 | AE44: 8.8211765 | AF44: 524.86 | AG44: 0.23391813 | AH44: 0.023391813 | AI44: 0.00094388572 | AJ44: 0.074074074
A45: 44712 | B45: 2022-05-28 12:43:42 | C45: სამგორი | D45: 1 | E45: Internet | F45: Lead | G45: Yes | L45: 45626 | M45: უნივერსიტეტი | N45: 58 | O45: 103 | P45: 797015 | Q45: 385574 | R45: 260041 | S45: 2215.43 | T45: 2685.34 | U45: 2685.34 | V45: 0 | W45: 50386 | X45: 75 | Y45: 3 | Z45: 427 | AA45: 1 | AB45: 2.067087 | AC45: 3.3692465 | AD45: 6.2888525 | AE45: 0.05329536 | AF45: 895.11333 | AG45: 0.13583138 | AH45: 0.0070257611 | AI45: 0.0016420488 | AJ45: 0.029126214
A46: 44712 | B46: 2022-05-28 14:42:06 | C46: უნივერსიტეტი | D46: 1 | E46: Other | F46: Lead | G46: Yes | L46: 45626 | M46: ყველა პროექტი | N46: 251 | O46: 342 | P46: 2118632 | Q46: 865398 | R46: 667107 | S46: 5664.19 | T46: 6583.94 | U46: 6583.94 | V46: 0 | W46: 51961 | X46: 227 | Y46: 39 | Z46: 1155 | AA46: 1 | AB46: 2.4481591 | AC46: 3.1076374 | AD46: 5.700381 | AE46: 0.12670926 | AF46: 168.81897 | AG46: 0.21731602 | AH46: 0.033766234 | AI46: 0.0017313564 | AJ46: 0.11403509
A47: 44712 | B47: 2022-05-28 14:52:59 | C47: სამგორი | D47: 1 | E47: Construction Site | F47: Lead | G47: Yes | L47: 45657 | M47: სამგორი | N47: 58 | O47: 81 | P47: 311936 | Q47: 97526 | R47: 97526 | S47: 898.87 | T47: 898.87 | U47: 898.87 | V47: 0 | W47: 316 | X47: 93 | Y47: 6 | Z47: 316 | AA47: 1 | AB47: 3.1984907 | AC47: 2.8815847 | AD47: 2.8445253 | AE47: 2.8445253 | AF47: 149.81167 | AG47: 0.1835443 | AH47: 0.018987342 | AI47: 0.0032401616 | AJ47: 0.074074074
A48: 44712 | B48: 2022-05-28 16:21:25 | C48: სამგორი | D48: 1 | E48: FB | F48: Lead | G48: Yes | L48: 45657 | M48: ლისი | N48: 13 | O48: 26 | P48: 387830 | Q48: 139436 | R48: 139436 | S48: 1399.85 | T48: 1399.85 | U48: 1399.85 | V48: 0 | W48: 157 | X48: 51 | Y48: 2 | Z48: 157 | AA48: 1 | AB48: 2.7814194 | AC48: 3.6094423 | AD48: 8.916242 | AE48: 8.916242 | AF48: 699.925 | AG48: 0.082802548 | AH48: 0.012738854 | AI48: 0.0011259646 | AJ48: 0.076923077
A49: 44712 | B49: 2022-05-30 11:15:19 | C49: სამგორი | D49: 1 | E49: FB | F49: Lead | G49: Yes | L49: 45657 | M49: უნივერსიტეტი | N49: 46 | O49: 72 | P49: 582852 | Q49: 257247 | R49: 257247 | S49: 1691.55 | T49: 1691.55 | U49: 1691.55 | V49: 0 | W49: 357 | X49: 170 | Y49: 13 | Z49: 357 | AA49: 1 | AB49: 2.265729 | AC49: 2.9021947 | AD49: 4.7382353 | AE49: 4.7382353 | AF49: 130.11923 | AG49: 0.12885154 | AH49: 0.036414566 | AI49: 0.0013877713 | AJ49: 0.18055556
A50: 44712 | B50: 2022-05-30 13:56:34 | C50: სამგორი | D50: 1 | E50: Construction Site | F50: Lead | G50: Yes | L50: 45657 | M50: ყველა პროექტი | N50: 117 | O50: 179 | P50: 1282618 | Q50: 494209 | R50: 494209 | S50: 3990.27 | T50: 3990.27 | U50: 3990.27 | V50: 0 | W50: 830 | X50: 314 | Y50: 21 | Z50: 830 | AA50: 1 | AB50: 2.5952947 | AC50: 3.1110354 | AD50: 4.8075542 | AE50: 4.8075542 | AF50: 190.01286 | AG50: 0.14096386 | AH50: 0.025301205 | AI50: 0.0016794514 | AJ50: 0.11731844
A51: 44712 | B51: 2022-05-30 14:39:59 | C51: სამგორი | D51: 1 | E51: FB | F51: Lead | G51: Yes | L51: 45688 | M51: სამგორი | N51: 145 | O51: 169 | P51: 1286305 | Q51: 469702 | R51: 386232 | S51: 2246.34 | T51: 2346.34 | U51: 2346.34 | V51: 0 | W51: 5353 | X51: 84 | Y51: 9 | Z51: 1406 | AA51: 1 | AB51: 2.7385555 | AC51: 1.824093 | AD51: 1.6688051 | AE51: 0.43832244 | AF51: 260.70444 | AG51: 0.10312945 | AH51: 0.006401138 | AI51: 0.0036402991 | AJ51: 0.053254438
A52: 44712 | B52: 2022-05-30 17:26:16 | C52: სამგორი | D52: 1 | E52: Construction Site | F52: Lead | G52: Yes | L52: 45688 | M52: ლისი | N52: 32 | O52: 42 | P52: 1417296 | Q52: 596763 | R52: 272460 | S52: 2473.37 | T52: 2973.34 | U52: 2973.34 | V52: 0 | W52: 22345 | X52: 51 | Y52: 0 | Z52: 334 | AA52: 1 | AB52: 2.374973 | AC52: 2.0978963 | AD52: 8.9022156 | AE52: 0.13306512 | AG52: 0.095808383 | AH52: 0 | AI52: 0.001225868 | AJ52: 0
A53: 44712 | B53: 2022-05-30 10:53:38 | C53: სამგორი | D53: 1 | E53: FB | F53: Lead | G53: Yes | L53: 45688 | M53: უნივერსიტეტი | N53: 58 | O53: 81 | P53: 2713832 | Q53: 880893 | R53: 308712 | S53: 2597.3 | T53: 3547.17 | U53: 3547.17 | V53: 0 | W53: 21630 | X53: 161 | Y53: 9 | Z53: 772 | AA53: 1 | AB53: 3.0807737 | AC53: 1.3070706 | AD53: 4.5947798 | AE53: 0.16399307 | AF53: 394.13 | AG53: 0.075129534 | AH53: 0.011658031 | AI53: 0.0025007126 | AJ53: 0.11111111
A54: 44712 | B54: 2022-05-30 11:22:37 | C54: სამგორი | D54: 1 | E54: Construction Site | F54: Lead | G54: Yes | L54: 45688 | M54: ყველა პროექტი | N54: 235 | O54: 292 | P54: 5417433 | Q54: 1947358 | R54: 967404 | S54: 7317.01 | T54: 8866.85 | U54: 8866.85 | V54: 0 | W54: 49328 | X54: 296 | Y54: 18 | Z54: 2512 | AA54: 1 | AB54: 2.7819399 | AC54: 1.6367254 | AD54: 3.529797 | AE54: 0.17975288 | AF54: 492.60278 | AG54: 0.093550955 | AH54: 0.0071656051 | AI54: 0.0025966401 | AJ54: 0.061643836
A55: 44712 | B55: 2022-05-30 11:32:07 | C55: სამგორი | D55: 1 | E55: FB | F55: Lead | G55: Yes | L55: 45716 | M55: სამგორი | N55: 109 | O55: 130 | P55: 568764 | Q55: 178165 | R55: 178165 | S55: 1248.89 | T55: 1248.89 | U55: 1248.89 | V55: 0 | W55: 453 | X55: 87 | Y55: 17 | Z55: 453 | AA55: 1 | AB55: 3.1923442 | AC55: 2.1957965 | AD55: 2.7569316 | AE55: 2.7569316 | AF55: 73.464118 | AG55: 0.2406181 | AH55: 0.037527594 | AI55: 0.0025425869 | AJ55: 0.13076923
...

Sheet Marketing Charts
B3: Sales | H3: Costs
B5: ='Marketing Data'!IM7 -> 142 | H5: ='Marketing Data'!IN6 -> $ 88,547.21

Sheet Charts
A1: თარიღი | B1: 46142
B3: ჯამი | C3: =EOMONTH(B1,-12) -> 45777 | D3: =EOMONTH(C3,1) -> 45808 | E3: =EOMONTH(D3,1) -> 45838 | F3: =EOMONTH(E3,1) -> 45869 | G3: =EOMONTH(F3,1) -> 45900 | H3: =EOMONTH(G3,1) -> 45930 | I3: =EOMONTH(H3,1) -> 45961 | J3: =EOMONTH(I3,1) -> 45991 | K3: =EOMONTH(J3,1) -> 46022 | ... O3: =EOMONTH(N3,1) -> 46142 | Q3: მიმდინარე წლის ჯამური მაჩვენებლები | W3: =COUNTIFS(LIST!$F:$F,Charts!$B$4,LIST!$B:$B,Charts!D$3,LIST!$A:$A,Charts!$B$8) -> 0
B4: საცხოვრებელი | R4: რა-ბა | S4: ღირებულება
B5: გაყიდვები | C5: =INDEX(REPORT!$3:$3,MATCH(Charts!C$3,REPORT!$1:$1)) -> 25 | D5: =INDEX(REPORT!$3:$3,MATCH(Charts!D$3,REPORT!$1:$1)) -> 40 | E5: =INDEX(REPORT!$3:$3,MATCH(Charts!E$3,REPORT!$1:$1)) -> 19 | F5: =INDEX(REPORT!$3:$3,MATCH(Charts!F$3,REPORT!$1:$1)) -> 23 | G5: =INDEX(REPORT!$3:$3,MATCH(Charts!G$3,REPORT!$1:$1)) -> 19 | H5: =INDEX(REPORT!$3:$3,MATCH(Charts!H$3,REPORT!$1:$1)) -> 27 | I5: =INDEX(REPORT!$3:$3,MATCH(Charts!I$3,REPORT!$1:$1)) -> 32 | J5: =INDEX(REPORT!$3:$3,MATCH(Charts!J$3,REPORT!$1:$1)) -> 23 | ... O5: =INDEX(REPORT!$3:$3,MATCH(Charts!O$3,REPORT!$1:$1)) -> 37 | Q5: საცხოვრებელი | R5: =REPORT!J3 -> 133 | S5: =REPORT!J15 -> 14060701
B6: სტოკი | C6: =INDEX(REPORT!$27:$27,MATCH(EOMONTH(Charts!$C$3,-1),REPORT!$1:$1,0)) -> 255 | D6: =C6-C5+COUNTIFS(LIST!$F:$F,Charts!$B$4,LIST!$B:$B,Charts!C$3) -> 230 | E6: =D6-D5+COUNTIFS(LIST!$F:$F,Charts!$B$4,LIST!$B:$B,Charts!D$3) -> 316 | F6: =E6-E5+COUNTIFS(LIST!$F:$F,Charts!$B$4,LIST!$B:$B,Charts!E$3) -> 297 | G6: =F6-F5+COUNTIFS(LIST!$F:$F,Charts!$B$4,LIST!$B:$B,Charts!F$3) -> 296 | H6: =G6-G5+COUNTIFS(LIST!$F:$F,Charts!$B$4,LIST!$B:$B,Charts!G$3) -> 321 | I6: =H6-H5+COUNTIFS(LIST!$F:$F,Charts!$B$4,LIST!$B:$B,Charts!H$3) -> 294 | J6: =I6-I5+COUNTIFS(LIST!$F:$F,Charts!$B$4,LIST!$B:$B,Charts!I$3) -> 262 | K6: =J6-J5+COUNTIFS(LIST!$F:$F,Charts!$B$4,LIST!$B:$B,Charts!J$3) -> 239 | ... O6: =N6-N5+COUNTIFS(LIST!$F:$F,Charts!$B$4,LIST!$B:$B,Charts!N$3) -> 214 | Q6: კომერციული | R6: =REPORT!J4 -> 6 | S6: =REPORT!J16 -> 844915
B7: % | C7: =C5/C6 -> 0.098039216 | D7: =D5/D6 -> 0.17391304 | E7: =E5/E6 -> 0.060126582 | F7: =F5/F6 -> 0.077441077 | G7: =G5/G6 -> 0.064189189 | H7: =H5/H6 -> 0.08411215 | I7: =I5/I6 -> 0.10884354 | J7: =J5/J6 -> 0.08778626 | ... O7: =O5/O6 -> 0.1728972 | Q7: პარკინგი | R7: =REPORT!J5+REPORT!J6 -> 21 | S7: =REPORT!J17+REPORT!J18 -> 180000
B8: სამგორი | Q8: სარდაფი | R8: =REPORT!J7 -> 4 | S8: =REPORT!J19 -> 21895
B9: საცხოვრებელი | Q9: ჯამი | R9: =SUM(R5:R8) -> 164 | S9: =SUM(S5:S8) -> 15107511
B10: გაყიდვები | C10: =INDEX(REPORT!$45:$45,MATCH(Charts!C$3,REPORT!$1:$1,0)) -> 13 | D10: =INDEX(REPORT!$45:$45,MATCH(Charts!D$3,REPORT!$1:$1,0)) -> 9 | E10: =INDEX(REPORT!$45:$45,MATCH(Charts!E$3,REPORT!$1:$1,0)) -> 4 | F10: =INDEX(REPORT!$45:$45,MATCH(Charts!F$3,REPORT!$1:$1,0)) -> 6 | G10: =INDEX(REPORT!$45:$45,MATCH(Charts!G$3,REPORT!$1:$1,0)) -> 7 | H10: =INDEX(REPORT!$45:$45,MATCH(Charts!H$3,REPORT!$1:$1,0)) -> 4 | I10: =INDEX(REPORT!$45:$45,MATCH(Charts!I$3,REPORT!$1:$1,0)) -> 9 | J10: =INDEX(REPORT!$45:$45,MATCH(Charts!J$3,REPORT!$1:$1,0)) -> 2 | ... O10: =INDEX(REPORT!$45:$45,MATCH(Charts!O$3,REPORT!$1:$1,0)) -> 0
B11: სტოკი | C11: =INDEX(REPORT!165:165,MATCH(EOMONTH(Charts!C3,-1),REPORT!1:1,0)) -> 74 | D11: =C11-C10+COUNTIFS(LIST!$F:$F,Charts!$B$4,LIST!$B:$B,Charts!C$3,LIST!$A:$A,Charts!$B$8) -> 61 | E11: =D11-D10+COUNTIFS(LIST!$F:$F,Charts!$B$4,LIST!$B:$B,Charts!D$3,LIST!$A:$A,Charts!$B$8) -> 52 | F11: =E11-E10+COUNTIFS(LIST!$F:$F,Charts!$B$4,LIST!$B:$B,Charts!E$3,LIST!$A:$A,Charts!$B$8) -> 48 | G11: =F11-F10+COUNTIFS(LIST!$F:$F,Charts!$B$4,LIST!$B:$B,Charts!F$3,LIST!$A:$A,Charts!$B$8) -> 42 | H11: =G11-G10+COUNTIFS(LIST!$F:$F,Charts!$B$4,LIST!$B:$B,Charts!G$3,LIST!$A:$A,Charts!$B$8) -> 35 | I11: =H11-H10+COUNTIFS(LIST!$F:$F,Charts!$B$4,LIST!$B:$B,Charts!H$3,LIST!$A:$A,Charts!$B$8) -> 31 | J11: =I11-I10+COUNTIFS(LIST!$F:$F,Charts!$B$4,LIST!$B:$B,Charts!I$3,LIST!$A:$A,Charts!$B$8) -> 22 | K11: =J11-J10+COUNTIFS(LIST!$F:$F,Charts!$B$4,LIST!$B:$B,Charts!J$3,LIST!$A:$A,Charts!$B$8) -> 20 | ... O11: =N11-N10+COUNTIFS(LIST!$F:$F,Charts!$B$4,LIST!$B:$B,Charts!N$3,LIST!$A:$A,Charts!$B$8) -> 4 | Q11: გაყიდვების მაჩვენებლები ქვეყნების მიხედვით
B12: % | C12: =C10/C11 -> 0.17567568 | D12: =D10/D11 -> 0.14754098 | E12: =E10/E11 -> 0.076923077 | F12: =F10/F11 -> 0.125 | G12: =G10/G11 -> 0.16666667 | H12: =H10/H11 -> 0.11428571 | I12: =I10/I11 -> 0.29032258 | J12: =J10/J11 -> 0.090909091 | ... O12: =O10/O11 -> 0 | Q12: ქვეყანა | R12: ჯამი | S12: 2023 | T12: 2024 | U12: 2025 | V12: 2026
B13: ლისი | Q13: {=_xlfn.UNIQUE(_xlfn._xlws.FILTER(SALES!$P$460:$P$5848,SALES!$P$460:$P$5848<>""))} -> საქართველო | R13: =S13+T13 -> 685 | S13: =COUNTIFS(SALES!$P:$P,Charts!$Q13,SALES!$C:$C,Charts!S$12,SALES!$F:$F,"საცხოვრებელი")+COUNTIFS(Consolidate!$P:$P,Charts!$Q13,Consolidate!$C:$C,Charts!S$12,Consolidate!$F:$F,"საცხოვრებელი") -> 390 | T13: =COUNTIFS(SALES!$P:$P,Charts!$Q13,SALES!$C:$C,Charts!T$12,SALES!$F:$F,"საცხოვრებელი")+COUNTIFS(Consolidate!$P:$P,Charts!$Q13,Consolidate!$C:$C,Charts!T$12,Consolidate!$F:$F,"საცხოვრებელი") -> 295 | U13: =COUNTIFS(SALES!$P:$P,Charts!$Q13,SALES!$C:$C,Charts!U$12,SALES!$F:$F,"საცხოვრებელი")+COUNTIFS(Consolidate!$P:$P,Charts!$Q13,Consolidate!$C:$C,Charts!U$12,Consolidate!$F:$F,"საცხოვრებელი") -> 265 | V13: =COUNTIFS(SALES!$P:$P,Charts!$Q13,SALES!$C:$C,Charts!V$12,SALES!$F:$F,"საცხოვრებელი")+COUNTIFS(Consolidate!$P:$P,Charts!$Q13,Consolidate!$C:$C,Charts!V$12,Consolidate!$F:$F,"საცხოვრებელი") -> 101
B14: საცხოვრებელი | Q14: რუსეთი | R14: =S14+T14 -> 40 | S14: =COUNTIFS(SALES!$P:$P,Charts!$Q14,SALES!$C:$C,Charts!S$12,SALES!$F:$F,"საცხოვრებელი")+COUNTIFS(Consolidate!$P:$P,Charts!$Q14,Consolidate!$C:$C,Charts!S$12,Consolidate!$F:$F,"საცხოვრებელი") -> 21 | T14: =COUNTIFS(SALES!$P:$P,Charts!$Q14,SALES!$C:$C,Charts!T$12,SALES!$F:$F,"საცხოვრებელი")+COUNTIFS(Consolidate!$P:$P,Charts!$Q14,Consolidate!$C:$C,Charts!T$12,Consolidate!$F:$F,"საცხოვრებელი") -> 19 | U14: =COUNTIFS(SALES!$P:$P,Charts!$Q14,SALES!$C:$C,Charts!U$12,SALES!$F:$F,"საცხოვრებელი")+COUNTIFS(Consolidate!$P:$P,Charts!$Q14,Consolidate!$C:$C,Charts!U$12,Consolidate!$F:$F,"საცხოვრებელი") -> 20 | V14: =COUNTIFS(SALES!$P:$P,Charts!$Q14,SALES!$C:$C,Charts!V$12,SALES!$F:$F,"საცხოვრებელი")+COUNTIFS(Consolidate!$P:$P,Charts!$Q14,Consolidate!$C:$C,Charts!V$12,Consolidate!$F:$F,"საცხოვრებელი") -> 20
B15: გაყიდვები | C15: =INDEX(REPORT!$51:$51,MATCH(Charts!C$3,REPORT!$1:$1,0)) -> 1 | D15: =INDEX(REPORT!$51:$51,MATCH(Charts!D$3,REPORT!$1:$1,0)) -> 4 | E15: =INDEX(REPORT!$51:$51,MATCH(Charts!E$3,REPORT!$1:$1,0)) -> 7 | F15: =INDEX(REPORT!$51:$51,MATCH(Charts!F$3,REPORT!$1:$1,0)) -> 7 | G15: =INDEX(REPORT!$51:$51,MATCH(Charts!G$3,REPORT!$1:$1,0)) -> 7 | H15: =INDEX(REPORT!$51:$51,MATCH(Charts!H$3,REPORT!$1:$1,0)) -> 13 | I15: =INDEX(REPORT!$51:$51,MATCH(Charts!I$3,REPORT!$1:$1,0)) -> 13 | J15: =INDEX(REPORT!$51:$51,MATCH(Charts!J$3,REPORT!$1:$1,0)) -> 8 | ... O15: =INDEX(REPORT!$51:$51,MATCH(Charts!O$3,REPORT!$1:$1,0)) -> 4 | Q15: ესტონეთი | R15: =S15+T15 -> 2 | S15: =COUNTIFS(SALES!$P:$P,Charts!$Q15,SALES!$C:$C,Charts!S$12,SALES!$F:$F,"საცხოვრებელი")+COUNTIFS(Consolidate!$P:$P,Charts!$Q15,Consolidate!$C:$C,Charts!S$12,Consolidate!$F:$F,"საცხოვრებელი") -> 2 | T15: =COUNTIFS(SALES!$P:$P,Charts!$Q15,SALES!$C:$C,Charts!T$12,SALES!$F:$F,"საცხოვრებელი")+COUNTIFS(Consolidate!$P:$P,Charts!$Q15,Consolidate!$C:$C,Charts!T$12,Consolidate!$F:$F,"საცხოვრებელი") -> 0 | U15: =COUNTIFS(SALES!$P:$P,Charts!$Q15,SALES!$C:$C,Charts!U$12,SALES!$F:$F,"საცხოვრებელი")+COUNTIFS(Consolidate!$P:$P,Charts!$Q15,Consolidate!$C:$C,Charts!U$12,Consolidate!$F:$F,"საცხოვრებელი") -> 0 | V15: =COUNTIFS(SALES!$P:$P,Charts!$Q15,SALES!$C:$C,Charts!V$12,SALES!$F:$F,"საცხოვრებელი")+COUNTIFS(Consolidate!$P:$P,Charts!$Q15,Consolidate!$C:$C,Charts!V$12,Consolidate!$F:$F,"საცხოვრებელი") -> 0
B16: სტოკი | C16: =INDEX(REPORT!$171:$171,MATCH(EOMONTH(Charts!$C$3,-1),REPORT!$1:$1,0)) -> 41 | D16: =C16-C15+COUNTIFS(LIST!$F:$F,Charts!$B$4,LIST!$B:$B,Charts!C$3,LIST!$A:$A,Charts!$B$13) -> 40 | E16: =D16-D15+COUNTIFS(LIST!$F:$F,Charts!$B$4,LIST!$B:$B,Charts!D$3,LIST!$A:$A,Charts!$B$13) -> 47 | F16: =E16-E15+COUNTIFS(LIST!$F:$F,Charts!$B$4,LIST!$B:$B,Charts!E$3,LIST!$A:$A,Charts!$B$13) -> 40 | G16: =F16-F15+COUNTIFS(LIST!$F:$F,Charts!$B$4,LIST!$B:$B,Charts!F$3,LIST!$A:$A,Charts!$B$13) -> 55 | H16: =G16-G15+COUNTIFS(LIST!$F:$F,Charts!$B$4,LIST!$B:$B,Charts!G$3,LIST!$A:$A,Charts!$B$13) -> 92 | I16: =H16-H15+COUNTIFS(LIST!$F:$F,Charts!$B$4,LIST!$B:$B,Charts!H$3,LIST!$A:$A,Charts!$B$13) -> 79 | J16: =I16-I15+COUNTIFS(LIST!$F:$F,Charts!$B$4,LIST!$B:$B,Charts!I$3,LIST!$A:$A,Charts!$B$13) -> 66 | K16: =J16-J15+COUNTIFS(LIST!$F:$F,Charts!$B$4,LIST!$B:$B,Charts!J$3,LIST!$A:$A,Charts!$B$13) -> 58 | ... O16: =N16-N15+COUNTIFS(LIST!$F:$F,Charts!$B$4,LIST!$B:$B,Charts!N$3,LIST!$A:$A,Charts!$B$13) -> 79 | Q16: ისრაელი | R16: =S16+T16 -> 2 | S16: =COUNTIFS(SALES!$P:$P,Charts!$Q16,SALES!$C:$C,Charts!S$12,SALES!$F:$F,"საცხოვრებელი")+COUNTIFS(Consolidate!$P:$P,Charts!$Q16,Consolidate!$C:$C,Charts!S$12,Consolidate!$F:$F,"საცხოვრებელი") -> 1 | T16: =COUNTIFS(SALES!$P:$P,Charts!$Q16,SALES!$C:$C,Charts!T$12,SALES!$F:$F,"საცხოვრებელი")+COUNTIFS(Consolidate!$P:$P,Charts!$Q16,Consolidate!$C:$C,Charts!T$12,Consolidate!$F:$F,"საცხოვრებელი") -> 1 | U16: =COUNTIFS(SALES!$P:$P,Charts!$Q16,SALES!$C:$C,Charts!U$12,SALES!$F:$F,"საცხოვრებელი")+COUNTIFS(Consolidate!$P:$P,Charts!$Q16,Consolidate!$C:$C,Charts!U$12,Consolidate!$F:$F,"საცხოვრებელი") -> 4 | V16: =COUNTIFS(SALES!$P:$P,Charts!$Q16,SALES!$C:$C,Charts!V$12,SALES!$F:$F,"საცხოვრებელი")+COUNTIFS(Consolidate!$P:$P,Charts!$Q16,Consolidate!$C:$C,Charts!V$12,Consolidate!$F:$F,"საცხოვრებელი") -> 1
B17: % | C17: =C15/C16 -> 0.024390244 | D17: =D15/D16 -> 0.1 | E17: =E15/E16 -> 0.14893617 | F17: =F15/F16 -> 0.175 | G17: =G15/G16 -> 0.12727273 | H17: =H15/H16 -> 0.14130435 | I17: =I15/I16 -> 0.16455696 | J17: =J15/J16 -> 0.12121212 | ... O17: =O15/O16 -> 0.050632911 | Q17: ესპანეთი | R17: =S17+T17 -> 2 | S17: =COUNTIFS(SALES!$P:$P,Charts!$Q17,SALES!$C:$C,Charts!S$12,SALES!$F:$F,"საცხოვრებელი")+COUNTIFS(Consolidate!$P:$P,Charts!$Q17,Consolidate!$C:$C,Charts!S$12,Consolidate!$F:$F,"საცხოვრებელი") -> 2 | T17: =COUNTIFS(SALES!$P:$P,Charts!$Q17,SALES!$C:$C,Charts!T$12,SALES!$F:$F,"საცხოვრებელი")+COUNTIFS(Consolidate!$P:$P,Charts!$Q17,Consolidate!$C:$C,Charts!T$12,Consolidate!$F:$F,"საცხოვრებელი") -> 0 | U17: =COUNTIFS(SALES!$P:$P,Charts!$Q17,SALES!$C:$C,Charts!U$12,SALES!$F:$F,"საცხოვრებელი")+COUNTIFS(Consolidate!$P:$P,Charts!$Q17,Consolidate!$C:$C,Charts!U$12,Consolidate!$F:$F,"საცხოვრებელი") -> 0 | V17: =COUNTIFS(SALES!$P:$P,Charts!$Q17,SALES!$C:$C,Charts!V$12,SALES!$F:$F,"საცხოვრებელი")+COUNTIFS(Consolidate!$P:$P,Charts!$Q17,Consolidate!$C:$C,Charts!V$12,Consolidate!$F:$F,"საცხოვრებელი") -> 0
B18: უნივერსიტეტი | Q18: სომხეთი | R18: =S18+T18 -> 4 | S18: =COUNTIFS(SALES!$P:$P,Charts!$Q18,SALES!$C:$C,Charts!S$12,SALES!$F:$F,"საცხოვრებელი")+COUNTIFS(Consolidate!$P:$P,Charts!$Q18,Consolidate!$C:$C,Charts!S$12,Consolidate!$F:$F,"საცხოვრებელი") -> 4 | T18: =COUNTIFS(SALES!$P:$P,Charts!$Q18,SALES!$C:$C,Charts!T$12,SALES!$F:$F,"საცხოვრებელი")+COUNTIFS(Consolidate!$P:$P,Charts!$Q18,Consolidate!$C:$C,Charts!T$12,Consolidate!$F:$F,"საცხოვრებელი") -> 0 | U18: =COUNTIFS(SALES!$P:$P,Charts!$Q18,SALES!$C:$C,Charts!U$12,SALES!$F:$F,"საცხოვრებელი")+COUNTIFS(Consolidate!$P:$P,Charts!$Q18,Consolidate!$C:$C,Charts!U$12,Consolidate!$F:$F,"საცხოვრებელი") -> 0 | V18: =COUNTIFS(SALES!$P:$P,Charts!$Q18,SALES!$C:$C,Charts!V$12,SALES!$F:$F,"საცხოვრებელი")+COUNTIFS(Consolidate!$P:$P,Charts!$Q18,Consolidate!$C:$C,Charts!V$12,Consolidate!$F:$F,"საცხოვრებელი") -> 0
B19: საცხოვრებელი | Q19: ირანი | R19: =S19+T19 -> 11 | S19: =COUNTIFS(SALES!$P:$P,Charts!$Q19,SALES!$C:$C,Charts!S$12,SALES!$F:$F,"საცხოვრებელი")+COUNTIFS(Consolidate!$P:$P,Charts!$Q19,Consolidate!$C:$C,Charts!S$12,Consolidate!$F:$F,"საცხოვრებელი") -> 2 | T19: =COUNTIFS(SALES!$P:$P,Charts!$Q19,SALES!$C:$C,Charts!T$12,SALES!$F:$F,"საცხოვრებელი")+COUNTIFS(Consolidate!$P:$P,Charts!$Q19,Consolidate!$C:$C,Charts!T$12,Consolidate!$F:$F,"საცხოვრებელი") -> 9 | U19: =COUNTIFS(SALES!$P:$P,Charts!$Q19,SALES!$C:$C,Charts!U$12,SALES!$F:$F,"საცხოვრებელი")+COUNTIFS(Consolidate!$P:$P,Charts!$Q19,Consolidate!$C:$C,Charts!U$12,Consolidate!$F:$F,"საცხოვრებელი") -> 2 | V19: =COUNTIFS(SALES!$P:$P,Charts!$Q19,SALES!$C:$C,Charts!V$12,SALES!$F:$F,"საცხოვრებელი")+COUNTIFS(Consolidate!$P:$P,Charts!$Q19,Consolidate!$C:$C,Charts!V$12,Consolidate!$F:$F,"საცხოვრებელი") -> 0
B20: გაყიდვები | C20: =INDEX(REPORT!$57:$57,MATCH(Charts!C$3,REPORT!$1:$1,0)) -> 11 | D20: =INDEX(REPORT!$57:$57,MATCH(Charts!D$3,REPORT!$1:$1,0)) -> 27 | E20: =INDEX(REPORT!$57:$57,MATCH(Charts!E$3,REPORT!$1:$1,0)) -> 8 | F20: =INDEX(REPORT!$57:$57,MATCH(Charts!F$3,REPORT!$1:$1,0)) -> 10 | G20: =INDEX(REPORT!$57:$57,MATCH(Charts!G$3,REPORT!$1:$1,0)) -> 5 | H20: =INDEX(REPORT!$57:$57,MATCH(Charts!H$3,REPORT!$1:$1,0)) -> 10 | I20: =INDEX(REPORT!$57:$57,MATCH(Charts!I$3,REPORT!$1:$1,0)) -> 10 | J20: =INDEX(REPORT!$57:$57,MATCH(Charts!J$3,REPORT!$1:$1,0)) -> 13 | ... O20: =INDEX(REPORT!$57:$57,MATCH(Charts!O$3,REPORT!$1:$1,0)) -> 33 | Q20: ბელორუსია | R20: =S20+T20 -> 6 | S20: =COUNTIFS(SALES!$P:$P,Charts!$Q20,SALES!$C:$C,Charts!S$12,SALES!$F:$F,"საცხოვრებელი")+COUNTIFS(Consolidate!$P:$P,Charts!$Q20,Consolidate!$C:$C,Charts!S$12,Consolidate!$F:$F,"საცხოვრებელი") -> 1 | T20: =COUNTIFS(SALES!$P:$P,Charts!$Q20,SALES!$C:$C,Charts!T$12,SALES!$F:$F,"საცხოვრებელი")+COUNTIFS(Consolidate!$P:$P,Charts!$Q20,Consolidate!$C:$C,Charts!T$12,Consolidate!$F:$F,"საცხოვრებელი") -> 5 | U20: =COUNTIFS(SALES!$P:$P,Charts!$Q20,SALES!$C:$C,Charts!U$12,SALES!$F:$F,"საცხოვრებელი")+COUNTIFS(Consolidate!$P:$P,Charts!$Q20,Consolidate!$C:$C,Charts!U$12,Consolidate!$F:$F,"საცხოვრებელი") -> 2 | V20: =COUNTIFS(SALES!$P:$P,Charts!$Q20,SALES!$C:$C,Charts!V$12,SALES!$F:$F,"საცხოვრებელი")+COUNTIFS(Consolidate!$P:$P,Charts!$Q20,Consolidate!$C:$C,Charts!V$12,Consolidate!$F:$F,"საცხოვრებელი") -> 1
B21: სტოკი | C21: =INDEX(REPORT!$177:$177,MATCH(EOMONTH(Charts!$C$3,-1),REPORT!$1:$1,0)) -> 140 | D21: =C21-C20+COUNTIFS(LIST!$F:$F,Charts!$B$4,LIST!$B:$B,Charts!C$3,LIST!$A:$A,Charts!$B$18) -> 129 | E21: =D21-D20+COUNTIFS(LIST!$F:$F,Charts!$B$4,LIST!$B:$B,Charts!D$3,LIST!$A:$A,Charts!$B$18) -> 217 | F21: =E21-E20+COUNTIFS(LIST!$F:$F,Charts!$B$4,LIST!$B:$B,Charts!E$3,LIST!$A:$A,Charts!$B$18) -> 209 | G21: =F21-F20+COUNTIFS(LIST!$F:$F,Charts!$B$4,LIST!$B:$B,Charts!F$3,LIST!$A:$A,Charts!$B$18) -> 199 | H21: =G21-G20+COUNTIFS(LIST!$F:$F,Charts!$B$4,LIST!$B:$B,Charts!G$3,LIST!$A:$A,Charts!$B$18) -> 194 | I21: =H21-H20+COUNTIFS(LIST!$F:$F,Charts!$B$4,LIST!$B:$B,Charts!H$3,LIST!$A:$A,Charts!$B$18) -> 184 | J21: =I21-I20+COUNTIFS(LIST!$F:$F,Charts!$B$4,LIST!$B:$B,Charts!I$3,LIST!$A:$A,Charts!$B$18) -> 174 | K21: =J21-J20+COUNTIFS(LIST!$F:$F,Charts!$B$4,LIST!$B:$B,Charts!J$3,LIST!$A:$A,Charts!$B$18) -> 161 | ... O21: =N21-N20+COUNTIFS(LIST!$F:$F,Charts!$B$4,LIST!$B:$B,Charts!N$3,LIST!$A:$A,Charts!$B$18) -> 131 | Q21: გერმანია | R21: =S21+T21 -> 5 | S21: =COUNTIFS(SALES!$P:$P,Charts!$Q21,SALES!$C:$C,Charts!S$12,SALES!$F:$F,"საცხოვრებელი")+COUNTIFS(Consolidate!$P:$P,Charts!$Q21,Consolidate!$C:$C,Charts!S$12,Consolidate!$F:$F,"საცხოვრებელი") -> 2 | T21: =COUNTIFS(SALES!$P:$P,Charts!$Q21,SALES!$C:$C,Charts!T$12,SALES!$F:$F,"საცხოვრებელი")+COUNTIFS(Consolidate!$P:$P,Charts!$Q21,Consolidate!$C:$C,Charts!T$12,Consolidate!$F:$F,"საცხოვრებელი") -> 3 | U21: =COUNTIFS(SALES!$P:$P,Charts!$Q21,SALES!$C:$C,Charts!U$12,SALES!$F:$F,"საცხოვრებელი")+COUNTIFS(Consolidate!$P:$P,Charts!$Q21,Consolidate!$C:$C,Charts!U$12,Consolidate!$F:$F,"საცხოვრებელი") -> 4 | V21: =COUNTIFS(SALES!$P:$P,Charts!$Q21,SALES!$C:$C,Charts!V$12,SALES!$F:$F,"საცხოვრებელი")+COUNTIFS(Consolidate!$P:$P,Charts!$Q21,Consolidate!$C:$C,Charts!V$12,Consolidate!$F:$F,"საცხოვრებელი") -> 0
B22: % | C22: =C20/C21 -> 0.078571429 | D22: =D20/D21 -> 0.20930233 | E22: =E20/E21 -> 0.036866359 | F22: =F20/F21 -> 0.04784689 | G22: =G20/G21 -> 0.025125628 | H22: =H20/H21 -> 0.051546392 | I22: =I20/I21 -> 0.054347826 | J22: =J20/J21 -> 0.074712644 | ... O22: =O20/O21 -> 0.2519084 | Q22: ბელგია | R22: =S22+T22 -> 1 | S22: =COUNTIFS(SALES!$P:$P,Charts!$Q22,SALES!$C:$C,Charts!S$12,SALES!$F:$F,"საცხოვრებელი")+COUNTIFS(Consolidate!$P:$P,Charts!$Q22,Consolidate!$C:$C,Charts!S$12,Consolidate!$F:$F,"საცხოვრებელი") -> 1 | T22: =COUNTIFS(SALES!$P:$P,Charts!$Q22,SALES!$C:$C,Charts!T$12,SALES!$F:$F,"საცხოვრებელი")+COUNTIFS(Consolidate!$P:$P,Charts!$Q22,Consolidate!$C:$C,Charts!T$12,Consolidate!$F:$F,"საცხოვრებელი") -> 0 | U22: =COUNTIFS(SALES!$P:$P,Charts!$Q22,SALES!$C:$C,Charts!U$12,SALES!$F:$F,"საცხოვრებელი")+COUNTIFS(Consolidate!$P:$P,Charts!$Q22,Consolidate!$C:$C,Charts!U$12,Consolidate!$F:$F,"საცხოვრებელი") -> 0 | V22: =COUNTIFS(SALES!$P:$P,Charts!$Q22,SALES!$C:$C,Charts!V$12,SALES!$F:$F,"საცხოვრებელი")+COUNTIFS(Consolidate!$P:$P,Charts!$Q22,Consolidate!$C:$C,Charts!V$12,Consolidate!$F:$F,"საცხოვრებელი") -> 0
Q23: უკრაინა | R23: =S23+T23 -> 6 | S23: =COUNTIFS(SALES!$P:$P,Charts!$Q23,SALES!$C:$C,Charts!S$12,SALES!$F:$F,"საცხოვრებელი")+COUNTIFS(Consolidate!$P:$P,Charts!$Q23,Consolidate!$C:$C,Charts!S$12,Consolidate!$F:$F,"საცხოვრებელი") -> 1 | T23: =COUNTIFS(SALES!$P:$P,Charts!$Q23,SALES!$C:$C,Charts!T$12,SALES!$F:$F,"საცხოვრებელი")+COUNTIFS(Consolidate!$P:$P,Charts!$Q23,Consolidate!$C:$C,Charts!T$12,Consolidate!$F:$F,"საცხოვრებელი") -> 5 | U23: =COUNTIFS(SALES!$P:$P,Charts!$Q23,SALES!$C:$C,Charts!U$12,SALES!$F:$F,"საცხოვრებელი")+COUNTIFS(Consolidate!$P:$P,Charts!$Q23,Consolidate!$C:$C,Charts!U$12,Consolidate!$F:$F,"საცხოვრებელი") -> 3 | V23: =COUNTIFS(SALES!$P:$P,Charts!$Q23,SALES!$C:$C,Charts!V$12,SALES!$F:$F,"საცხოვრებელი")+COUNTIFS(Consolidate!$P:$P,Charts!$Q23,Consolidate!$C:$C,Charts!V$12,Consolidate!$F:$F,"საცხოვრებელი") -> 2
B24: check | C24: =C6-C11-C16-C21 -> 0 | D24: =D6-D11-D16-D21 -> 0 | E24: =E6-E11-E16-E21 -> 0 | F24: =F6-F11-F16-F21 -> 0 | G24: =G6-G11-G16-G21 -> 0 | H24: =H6-H11-H16-H21 -> 0 | I24: =I6-I11-I16-I21 -> 0 | J24: =J6-J11-J16-J21 -> 0 | ... O24: =O6-O11-O16-O21 -> 0 | Q24: ტუნისი | R24: =S24+T24 -> 1 | S24: =COUNTIFS(SALES!$P:$P,Charts!$Q24,SALES!$C:$C,Charts!S$12,SALES!$F:$F,"საცხოვრებელი")+COUNTIFS(Consolidate!$P:$P,Charts!$Q24,Consolidate!$C:$C,Charts!S$12,Consolidate!$F:$F,"საცხოვრებელი") -> 1 | T24: =COUNTIFS(SALES!$P:$P,Charts!$Q24,SALES!$C:$C,Charts!T$12,SALES!$F:$F,"საცხოვრებელი")+COUNTIFS(Consolidate!$P:$P,Charts!$Q24,Consolidate!$C:$C,Charts!T$12,Consolidate!$F:$F,"საცხოვრებელი") -> 0 | U24: =COUNTIFS(SALES!$P:$P,Charts!$Q24,SALES!$C:$C,Charts!U$12,SALES!$F:$F,"საცხოვრებელი")+COUNTIFS(Consolidate!$P:$P,Charts!$Q24,Consolidate!$C:$C,Charts!U$12,Consolidate!$F:$F,"საცხოვრებელი") -> 0 | V24: =COUNTIFS(SALES!$P:$P,Charts!$Q24,SALES!$C:$C,Charts!V$12,SALES!$F:$F,"საცხოვრებელი")+COUNTIFS(Consolidate!$P:$P,Charts!$Q24,Consolidate!$C:$C,Charts!V$12,Consolidate!$F:$F,"საცხოვრებელი") -> 0
Q25: ამერიკა | R25: =S25+T25 -> 1 | S25: =COUNTIFS(SALES!$P:$P,Charts!$Q25,SALES!$C:$C,Charts!S$12,SALES!$F:$F,"საცხოვრებელი")+COUNTIFS(Consolidate!$P:$P,Charts!$Q25,Consolidate!$C:$C,Charts!S$12,Consolidate!$F:$F,"საცხოვრებელი") -> 1 | T25: =COUNTIFS(SALES!$P:$P,Charts!$Q25,SALES!$C:$C,Charts!T$12,SALES!$F:$F,"საცხოვრებელი")+COUNTIFS(Consolidate!$P:$P,Charts!$Q25,Consolidate!$C:$C,Charts!T$12,Consolidate!$F:$F,"საცხოვრებელი") -> 0 | U25: =COUNTIFS(SALES!$P:$P,Charts!$Q25,SALES!$C:$C,Charts!U$12,SALES!$F:$F,"საცხოვრებელი")+COUNTIFS(Consolidate!$P:$P,Charts!$Q25,Consolidate!$C:$C,Charts!U$12,Consolidate!$F:$F,"საცხოვრებელი") -> 0 | V25: =COUNTIFS(SALES!$P:$P,Charts!$Q25,SALES!$C:$C,Charts!V$12,SALES!$F:$F,"საცხოვრებელი")+COUNTIFS(Consolidate!$P:$P,Charts!$Q25,Consolidate!$C:$C,Charts!V$12,Consolidate!$F:$F,"საცხოვრებელი") -> 1
